Workbook
Name Datenschnitt_Gruppe: #N/A
Name Datenschnitt_Gruppe1: #N/A
Name Datenschnitt_Händler: #N/A
Name Datenschnitt_Kategorie: #N/A
Name Datenschnitt_Kategorie1: #N/A
Name Datenschnitt_Kundenhierarchie_1: #N/A
Name Datenschnitt_Name: #N/A
Name Datenschnitt_Name1: #N/A
Name Datenschnitt_SKU_Type: #N/A
Name Datenschnitt_SKU_Type1: #N/A

Sheet Info
A4: Datenstand
A5: Circana | B5: Q4 2023
A6: Mobile Touch Listung | B6: 44973
A7: Mobile Touch Distribution | B7: 01.10.2023 - 31.12.2023
A9: Daten Warengruppen
A10: Gurken | B10: MT (Listung + Distribution), Circana
A11: Essig | B11: MT (Listung + Distribution), Circana
A12: Dressing | B12: MT (Listung + Distribution), Circana
A13: Würzsaucen | B13: MT (Listung + Distribution), Circana
A14: Senf | B14: MT (Listung), Circana
A15: Gemüse in Essig | B15: MT (Listung), Circana
A17: Daten Kunden
A18: Edeka Konzern
A19: Edeka Hessenring (ZL) | B19: MT (Listung + Distribution), Circana
A20: Edeka Minden (ZL + Lüning) | B20: MT (Listung + Distribution), Circana
A21: Edeka Nord (ZL) | B21: MT (Listung + Distribution), Circana
A22: Edeka Nordbayern (ZL) | B22: MT (Listung + Distribution), Circana
A23: Edeka Rhein Ruhr (ZL) | B23: MT (Listung + Distribution), Circana
A24: Edeka Südbayern (ZL) | B24: MT (Listung + Distribution), Circana
A25: Edeka Südwest (ZL) | B25: MT (Listung + Distribution), Circana
A26: Rewe Gruppe
A27: Rewe Mitte | B27: MT (Listung + Distribution), Circana
A28: Rewe Nord | B28: MT (Listung + Distribution), Circana
A29: Rewe Ost | B29: MT (Listung + Distribution), Circana
A30: Rewe Süd | B30: MT (Listung + Distribution), Circana
A31: Rewe Südwest | B31: MT (Listung + Distribution), Circana
A32: Rewe West | B32: MT (Listung + Distribution), Circana
A33: Rewe Dortmund | B33: MT (Listung + Distribution)
A34: mein real | B34: MT (Listung + Distribution), Circana
A35: Hit | B35: MT (Listung + Distribution)
A36: Wasgau | B36: MT (Listung + Distribution)
A37: Markant Services International GmbH
A38: Kaufland | B38: MT (Listung + Distribution)
A39: Bartels-Langness | B39: MT (Listung + Distribution)
A40: Bünting (ZL) | B40: MT (Listung + Distribution)
A41: Globus | B41: MT (Listung + Distribution)
A42: Kaes | B42: MT (Listung + Distribution)
B89: Alle "Mobile Touch"-Märkte (mit theoretischer Listung) | C89: Alle besuchten "Mobile Touch"-Märkte
A90: Edeka Konzern | B90: 3085 | C90: 1968
A91: Rewe Gruppe | B91: 2876 | C91: 1602
...

Sheet Produkte -> Händler
F3: Bünting (ZL)
F4: Listung % | G4: MT Distri % (besucht) | H4: MT Distri % VÄ vs. Vor-Quartal | I4: Cir nDistr (ohne Promo) | J4: Cir nDistr VÄ vs. VJ | K4: Cir gewDistr (ohne Promo) | L4: Cir gewDistr VÄ vs. VJ
C5: Top (Hero) | D5: 1 | E5: Kühne Condimento Bals. Bianco, 0,5l Kar. | F5: 1 | G5: 0.92481203 | H5: 1.8829124 | I5: 0 | J5: 0 | K5: 0 | L5: 0
D6: 2 | E6: Kühne Aceto Bals. di Modena,0,5l Karaffe | F6: 1 | G6: 0.97744361 | H6: -0.54623739 | I6: 0 | J6: 0 | K6: 0 | L6: 0
D7: 3 | E7: Surol 7-Krt Essig, 0,75l Fl. | F7: 1 | G7: 0.9924812 | H7: 0.95752201 | I7: 0 | J7: 0 | K7: 0 | L7: 0
D8: 4 | E8: Balsamissimo Balsamico-Creme 215ml Fl. | F8: 0 | G8: 0.98496241 | H8: 0.20564231 | I8: 0 | J8: 0 | K8: 0 | L8: 0
D9: 5 | E9: Salata kräuterwürzig, 0,75l Glasflasche | F9: 0.88235294 | G9: 0.59398496 | H9: 4.6976415 | I9: 0 | J9: 0 | K9: 0 | L9: 0
D10: 6 | E10: Apfelessig 5%, 0,75l Fl. | F10: 1 | G10: 0.9924812 | H10: 0.95752201 | I10: 0 | J10: 0 | K10: 0 | L10: 0
D11: 7 | E11: Kühne Weißweinessig 6%, 0,5l Karaffe | F11: 0.88235294 | G11: 0.77443609 | H11: 5.6487372 | I11: 0 | J11: 0 | K11: 0 | L11: 0
D12: 8 | E12: KFM Kressi Kräuter VollwEs.5% 0,75l 12er | F12: 0 | G12: 0 | H12: 0 | I12: 0 | J12: 0 | K12: 0 | L12: 0
D13: 9 | E13: Prem. Aceto Balsamico di Modena, 6x500ml | F13: 0 | G13: 0 | H13: 0 | I13: 0 | J13: 0 | K13: 0 | L13: 0
D14: 10 | E14: Kühne Essig-Essenz, 400g, 10er Tray | F14: 1 | G14: 0.9924812 | H14: 0.10282116 | I14: 0 | J14: 0 | K14: 0 | L14: 0
D15: 11 | E15: Premium Condimento Bianco, 6x500ml | F15: 0 | G15: 0 | H15: 0 | I15: 0 | J15: 0 | K15: 0 | L15: 0
C16: Ergänzung | D16: 12 | E16: Kühne Apfel Essig, 250ml Karaffe | F16: 0.88235294 | G16: 0.98496241 | H16: -0.64905854 | I16: 0 | J16: 0 | K16: 0 | L16: 0
D17: 13 | E17: Kühne Kräuteressig 5%, 0,5l Karaffe | F17: 0 | G17: 0 | H17: 0 | I17: 0 | J17: 0 | K17: 0 | L17: 0
D18: 14 | E18: Kühne Bio Apfel Essig 5% 0,5l Fl. | F18: 0.88235294 | G18: 0.96240602 | H18: 2.2235075 | I18: 0 | J18: 0 | K18: 0 | L18: 0
D19: 15 | E19: Kühne Cond.Balsam. Bianco, 250ml Karaffe | F19: 1 | G19: 0.98496241 | H19: -0.64905854 | I19: 0 | J19: 0 | K19: 0 | L19: 0
D20: 16 | E20: Kühne Aceto Balsamico, 100ml Flasche | F20: 0.88235294 | G20: 0.86466165 | H20: -4.1321252 | I20: 0 | J20: 0 | K20: 0 | L20: 0
D21: 17 | E21: Kühne Condim.Balsamico Bianco, 100ml Fl. | F21: 0 | G21: 0 | H21: 0 | I21: 0 | J21: 0 | K21: 0 | L21: 0
D22: 18 | E22: Himbeer & Essig, 250 ml Karaffe | F22: 0.74019608 | G22: 0.992 | H22: 0.084955752 | I22: 0 | J22: 0 | K22: 0 | L22: 0
D23: 19 | E23: Kühne Aceto Balsamico di Modena, 250ml | F23: 0.88235294 | G23: 0.98496241 | H23: 0.20564231 | I23: 0 | J23: 0 | K23: 0 | L23: 0
D24: 20 | E24: Tafelessig 5%, 0,75l Glasflasche | F24: 1 | G24: 0.9924812 | H24: 0.10282116 | I24: 0 | J24: 0 | K24: 0 | L24: 0
D25: 21 | E25: Weinwürziger Essig 5%, 0,75l Glasflasche | F25: 1 | G25: 0.9924812 | H25: 0.95752201 | I25: 0 | J25: 0 | K25: 0 | L25: 0
C26: Completion | D26: 22 | E26: Kühne Weißwein Essig, 250ml Karaffe | F26: 0 | G26: 0 | H26: 0 | I26: 0 | J26: 0 | K26: 0 | L26: 0
D27: 23 | E27: Kühne Rotweinessig 6%, 0,5l Karaffe | F27: 0 | G27: 0 | H27: 0 | I27: 0 | J27: 0 | K27: 0 | L27: 0
D28: 24 | E28: Honig & Essig, 250ml Karaffe | F28: 0 | G28: 0 | H28: 0 | I28: 0 | J28: 0 | K28: 0 | L28: 0
D29: 25 | E29: Walnuss & Essig, 250 ml Karaffe | F29: 0 | G29: 0 | H29: 0 | I29: 0 | J29: 0 | K29: 0 | L29: 0
D30: 26 | E30: Gurkenaufguss, 0,75l Glasfl. | F30: 0 | G30: 0 | H30: 0 | I30: 0 | J30: 0 | K30: 0 | L30: 0
D31: 27 | E31: KFM Kressi Kr. vollwürziger Essig 5l Kan | F31: 0 | G31: 0 | H31: 0 | I31: 0 | J31: 0 | K31: 0 | L31: 0
D32: 28 | E32: Kühne Weißweinessig, 100ml Flasche | F32: 0 | G32: 0 | H32: 0 | I32: 0 | J32: 0 | K32: 0 | L32: 0
D33: 29 | E33: Essig plus Zitrone, 0,75l Glasfl. | F33: 0 | G33: 0 | H33: 0 | I33: 0 | J33: 0 | K33: 0 | L33: 0
D34: 30 | E34: Balsamissimo Basilikum, 215ml Fl. | F34: 0 | G34: 0 | H34: 0 | I34: 0 | J34: 0 | K34: 0 | L34: 0
D35: 31 | E35: Kühne Rotwein Essig, 250ml Karaffe | F35: 0 | G35: 0 | H35: 0 | I35: 0 | J35: 0 | K35: 0 | L35: 0
D36: 32 | E36: Vitasur Apfelessig-Trank, 0,75l Glasfl. | F36: 0 | G36: 0 | H36: 0 | I36: 0 | J36: 0 | K36: 0 | L36: 0
D37: 33 | E37: Bio Condimento Balsamico Bianco 5%,250ml | F37: 0 | G37: 0 | H37: 0 | I37: 0 | J37: 0 | K37: 0 | L37: 0
D38: 34 | E38: Gurkenaufguss, 2l Kanister | F38: 0 | G38: 0 | H38: 0 | I38: 0 | J38: 0 | K38: 0 | L38: 0
... D41: 99 | E41: Kuehne Aceto Bals.di Modena 6%, 2l Kan. | F41: 0 | G41: 0 | H41: 0 | I41: 0 | J41: 0 | K41: 0 | L41: 0
E42: Kuehne Condimento Balsa.Bianco, 2l Kan. | F42: 0 | G42: 0 | H42: 0 | I42: 0 | J42: 0 | K42: 0 | L42: 0
E43: Kuehne Rotweinessig 6%, 2l Kanister | F43: 0 | G43: 0 | H43: 0 | I43: 0 | J43: 0 | K43: 0 | L43: 0
E44: Kuehne Weissweinessig 6%, 2l Kanister | F44: 0 | G44: 0 | H44: 0 | I44: 0 | J44: 0 | K44: 0 | L44: 0
...

Sheet Tabelle1
A1: ID | B1: Name | C1: Ext. no.. | D1: EAN
A2: 171 | B2: Pickled Gherkins Russian Style 720ml | C2: 40545 | D2: 40122144
A3: 599 | B3: Gurken Moskauer Art, 720ml Glas 8er Tray | C3: 40542 | D3: 40122144
A4: 149 | B4: Danish Gherkins salad, 720ml | C4: 42860 | D4: 40804019
A5: 602 | B5: cucumber salad danish style, 720ml jars | C5: 42866 | D5: 40804019
A6: 155 | B6: Silesian cucumber rounds, 720ml jars | C6: 44480 | D6: 40804552
A7: 603 | B7: silesian cucumber rounds, 720ml jars 8er | C7: 44482 | D7: 40804552
A8: 167 | B8: Pickled dill rounds, 720ml | C8: 40870 | D8: 40804583
A9: 601 | B9: Dillschnitten, 720ml Glas, 8er Tray | C9: 40876 | D9: 40804583
A10: 154 | B10: Salt and dill gherkins, 720ml | C10: 48520 | D10: 40804606
A11: 604 | B11: Salt and dill gherkins, 720ml 8er | C11: 48525 | D11: 40804606
A12: 165 | B12: Gherkin Quarters, 720ml | C12: 40590 | D12: 40804705
A13: 600 | B13: Gurkenviertel, 720ml Glas 8er Tray | C13: 40625 | D13: 40804705
... A29: 607 | B29: Schlemmert. Bals. Bianco, 580ml, 8er | C29: 41764 | D29: 4012200417607

Sheet Produkte -> Händler Märkte
F3: Bünting (ZL)
F4: MT Märkte - gesamt | G4: MT Märkte - Listung | H4: MT Märkte - besucht | I4: Circana Märkte
C5: Top (Hero) | D5: 1 | E5: Kühne Condimento Bals. Bianco, 0,5l Kar. | F5: 204 | G5: 204 | H5: 133 | I5: 0
D6: 2 | E6: Kühne Aceto Bals. di Modena,0,5l Karaffe | F6: 204 | G6: 204 | H6: 133 | I6: 0
D7: 3 | E7: Surol 7-Krt Essig, 0,75l Fl. | F7: 204 | G7: 204 | H7: 133 | I7: 0
D8: 4 | E8: Balsamissimo Balsamico-Creme 215ml Fl. | F8: 204 | G8: 0 | H8: 133 | I8: 0
D9: 5 | E9: Salata kräuterwürzig, 0,75l Glasflasche | F9: 204 | G9: 180 | H9: 133 | I9: 0
D10: 6 | E10: Apfelessig 5%, 0,75l Fl. | F10: 204 | G10: 204 | H10: 133 | I10: 0
D11: 7 | E11: Kühne Weißweinessig 6%, 0,5l Karaffe | F11: 204 | G11: 180 | H11: 133 | I11: 0
D12: 8 | E12: KFM Kressi Kräuter VollwEs.5% 0,75l 12er | F12: 204 | G12: 0 | H12: 1 | I12: 0
D13: 9 | E13: Prem. Aceto Balsamico di Modena, 6x500ml | F13: 204 | G13: 0 | H13: 1 | I13: 0
D14: 10 | E14: Kühne Essig-Essenz, 400g, 10er Tray | F14: 204 | G14: 204 | H14: 133 | I14: 0
D15: 11 | E15: Premium Condimento Bianco, 6x500ml | F15: 204 | G15: 0 | H15: 1 | I15: 0
C16: Ergänzung | D16: 12 | E16: Kühne Apfel Essig, 250ml Karaffe | F16: 204 | G16: 180 | H16: 133 | I16: 0
D17: 13 | E17: Kühne Kräuteressig 5%, 0,5l Karaffe | F17: 204 | G17: 0 | H17: 1 | I17: 0
D18: 14 | E18: Kühne Bio Apfel Essig 5% 0,5l Fl. | F18: 204 | G18: 180 | H18: 133 | I18: 0
D19: 15 | E19: Kühne Cond.Balsam. Bianco, 250ml Karaffe | F19: 204 | G19: 204 | H19: 133 | I19: 0
D20: 16 | E20: Kühne Aceto Balsamico, 100ml Flasche | F20: 204 | G20: 180 | H20: 133 | I20: 0
D21: 17 | E21: Kühne Condim.Balsamico Bianco, 100ml Fl. | F21: 204 | G21: 0 | H21: 1 | I21: 0
D22: 18 | E22: Himbeer & Essig, 250 ml Karaffe | F22: 204 | G22: 151 | H22: 125 | I22: 0
D23: 19 | E23: Kühne Aceto Balsamico di Modena, 250ml | F23: 204 | G23: 180 | H23: 133 | I23: 0
D24: 20 | E24: Tafelessig 5%, 0,75l Glasflasche | F24: 204 | G24: 204 | H24: 133 | I24: 0
D25: 21 | E25: Weinwürziger Essig 5%, 0,75l Glasflasche | F25: 204 | G25: 204 | H25: 133 | I25: 0
C26: Completion | D26: 22 | E26: Kühne Weißwein Essig, 250ml Karaffe | F26: 204 | G26: 0 | H26: 1 | I26: 0
D27: 23 | E27: Kühne Rotweinessig 6%, 0,5l Karaffe | F27: 204 | G27: 0 | H27: 1 | I27: 0
D28: 24 | E28: Honig & Essig, 250ml Karaffe | F28: 204 | G28: 0 | H28: 1 | I28: 0
D29: 25 | E29: Walnuss & Essig, 250 ml Karaffe | F29: 204 | G29: 0 | H29: 1 | I29: 0
D30: 26 | E30: Gurkenaufguss, 0,75l Glasfl. | F30: 204 | G30: 0 | H30: 1 | I30: 0
D31: 27 | E31: KFM Kressi Kr. vollwürziger Essig 5l Kan | F31: 204 | G31: 0 | H31: 1 | I31: 0
D32: 28 | E32: Kühne Weißweinessig, 100ml Flasche | F32: 204 | G32: 0 | H32: 1 | I32: 0
D33: 29 | E33: Essig plus Zitrone, 0,75l Glasfl. | F33: 204 | G33: 0 | H33: 1 | I33: 0
D34: 30 | E34: Balsamissimo Basilikum, 215ml Fl. | F34: 204 | G34: 0 | H34: 1 | I34: 0
D35: 31 | E35: Kühne Rotwein Essig, 250ml Karaffe | F35: 204 | G35: 0 | H35: 1 | I35: 0
D36: 32 | E36: Vitasur Apfelessig-Trank, 0,75l Glasfl. | F36: 204 | G36: 0 | H36: 1 | I36: 0
D37: 33 | E37: Bio Condimento Balsamico Bianco 5%,250ml | F37: 204 | G37: 0 | H37: 1 | I37: 0
D38: 34 | E38: Gurkenaufguss, 2l Kanister | F38: 204 | G38: 0 | H38: 1 | I38: 0
... D41: 99 | E41: Kuehne Aceto Bals.di Modena 6%, 2l Kan. | F41: 204 | G41: 0 | H41: 1 | I41: 0
E42: Kuehne Condimento Balsa.Bianco, 2l Kan. | F42: 204 | G42: 0 | H42: 1 | I42: 0
E43: Kuehne Rotweinessig 6%, 2l Kanister | F43: 204 | G43: 0 | H43: 1 | I43: 0
E44: Kuehne Weissweinessig 6%, 2l Kanister | F44: 204 | G44: 0 | H44: 1 | I44: 0
...

Sheet Händler -> Produkte
D3: Top (Hero)
D4: 1 | K4: 2 | R4: 5 | Y4: 10
D5: Kühne Dressing Joghurt 0,5l | K5: Kühne Dressing Kräuterwürzig 0,5l | R5: Kühne Dressing Jogh.-Kräuter leicht 0,5l | Y5: Kühne Dressing French 0,5l
D6: Listung % | E6: MT Distri % (besucht) | F6: MT Distri % VÄ vs. Vor-Quartal | G6: Cir nDistr (ohne Promo) | H6: Cir nDistr VÄ vs. VJ | I6: Cir gewDistr (ohne Promo) | J6: Cir gewDistr VÄ vs. VJ | K6: Listung % | L6: MT Distri % (besucht) | M6: MT Distri % VÄ vs. Vor-Quartal | N6: Cir nDistr (ohne Promo) | O6: Cir nDistr VÄ vs. VJ | P6: Cir gewDistr (ohne Promo) | Q6: Cir gewDistr VÄ vs. VJ | R6: Listung % | S6: MT Distri % (besucht) | T6: MT Distri % VÄ vs. Vor-Quartal | U6: Cir nDistr (ohne Promo) | V6: Cir nDistr VÄ vs. VJ | W6: Cir gewDistr (ohne Promo) | X6: Cir gewDistr VÄ vs. VJ | Y6: Listung % | Z6: MT Distri % (besucht) | AA6: MT Distri % VÄ vs. Vor-Quartal | AB6: Cir nDistr (ohne Promo) | AC6: Cir nDistr VÄ vs. VJ | AD6: Cir gewDistr (ohne Promo) | AE6: Cir gewDistr VÄ vs. VJ
C7: Rewe Gruppe
C8: Hit | D8: 1 | E8: 0.98795181 | F8: 1.1481219 | G8: 0 | H8: 0 | I8: 0 | J8: 0 | K8: 1 | L8: 0.98795181 | M8: 1.1481219 | N8: 0 | O8: 0 | P8: 0 | Q8: 0 | R8: 1 | S8: 0.98795181 | T8: 1.1481219 | U8: 0 | V8: 0 | W8: 0 | X8: 0 | Y8: 1 | Z8: 0.98795181 | AA8: 1.1481219 | AB8: 0 | AC8: 0 | AD8: 0 | AE8: 0
C9: mein real | D9: 1 | E9: 0.98113208 | F9: 0.19654088 | G9: 100 | H9: 1.1494253 | I9: 100 | J9: 0.39813829 | K9: 1 | L9: 0.98113208 | M9: 2.2798742 | N9: 100 | O9: 3.4482759 | P9: 100 | Q9: 2.0894773 | R9: 1 | S9: 0.98113208 | T9: 0.19654088 | U9: 100 | V9: 3.4482759 | W9: 100 | X9: 1.737296 | Y9: 1 | Z9: 0.98113208 | AA9: 0.19654088 | AB9: 96.774194 | AC9: 0.22246941 | AD9: 97.655133 | AE9: -0.67674244
C10: Rewe Dortmund | D10: 1 | E10: 0.99494949 | F10: -0.0484295 | G10: 0 | H10: 0 | I10: 0 | J10: 0 | K10: 1 | L10: 0.98484848 | M10: -0.1452885 | N10: 0 | O10: 0 | P10: 0 | Q10: 0 | R10: 1 | S10: 0.97474747 | T10: 0.2144735 | U10: 0 | V10: 0 | W10: 0 | X10: 0 | Y10: 1 | Z10: 0.97979798 | AA10: 2.089387 | AB10: 0 | AC10: 0 | AD10: 0 | AE10: 0
C11: Rewe Mitte | D11: 1 | E11: 0.97938144 | F11: -0.06185567 | G11: 83.624454 | H11: 1.6116062 | I11: 91.241929 | J11: 1.2214247 | K11: 1 | L11: 0.95876289 | M11: -0.12371134 | N11: 83.406114 | O11: 0.75086728 | P11: 91.298666 | Q11: 0.8288591 | R11: 1 | S11: 0.97938144 | T11: 2.9381443 | U11: 82.31441 | V11: 0.087429752 | W11: 90.511322 | X11: 0.33443858 | Y11: 1 | Z11: 0.68041237 | AA11: 0.041237113 | AB11: 43.231441 | AC11: 6.1864732 | AD11: 56.989273 | AE11: 4.6445684
C12: Rewe Nord | D12: 1 | E12: 0.97849462 | F12: -1.2733447 | G12: 91.528239 | H12: -2.1066017 | I12: 95.787853 | J12: -0.88187802 | K12: 1 | L12: 0.97849462 | M12: -0.39615167 | N12: 87.873754 | O12: -1.4059778 | P12: 92.432599 | Q12: -0.38295254 | R12: 1 | S12: 0.94623656 | T12: -0.99037917 | U12: 79.23588 | V12: -1.1661297 | W12: 85.164301 | X12: -1.4670466 | Y12: 1 | Z12: 0.96774194 | AA12: -1.4714205 | AB12: 87.043189 | AC12: -1.9015342 | AD12: 91.207917 | AE12: -1.9424375
C13: Rewe Ost | D13: 1 | E13: 0.98412698 | F13: 0.73827981 | G13: 96.271186 | H13: 0.54469071 | I13: 97.844488 | J13: 0.31703118 | K13: 1 | L13: 0.65873016 | M13: 4.6327058 | N13: 61.694915 | O13: 12.976967 | P13: 69.441374 | Q13: 12.366481 | R13: 1 | S13: 0.87301587 | T13: -3.3960871 | U13: 89.152542 | V13: -0.93292771 | W13: 91.935775 | X13: -0.97616831 | Y13: 1 | Z13: 0.54761905 | AA13: 3.5991141 | AB13: 65.59322 | AC13: 15.33681 | AD13: 72.154975 | AE13: 14.259413
C14: Rewe Süd | D14: 1 | E14: 0.99122807 | F14: 0.43859649 | G14: 80.887372 | H14: 1.9218548 | I14: 86.122702 | J14: 1.6503068 | K14: 1 | L14: 0.99122807 | M14: 0.43859649 | N14: 92.491468 | O14: 2.14664 | P14: 95.888875 | Q14: 1.4873721 | R14: 1 | S14: 0.77192982 | T14: 14.035088 | U14: 82.25256 | V14: 29.838767 | W14: 88.35921 | X14: 27.257264 | Y14: 1 | Z14: 0.13157895 | AA14: -1.3157895 | AB14: 8.1911263 | AC14: 0.60491938 | AD14: 12.221375 | AE14: 0.90048836
C15: Rewe Südwest | D15: 1 | E15: 0.95774648 | F15: -2.5586854 | G15: 91.767554 | H15: 0.10088781 | I15: 95.588183 | J15: 0.47367729 | K15: 1 | L15: 0.97183099 | M15: 0.51643192 | N15: 96.368039 | O15: 0.28960737 | P15: 98.201549 | Q15: 0.3423102 | R15: 1 | S15: 0.97183099 | T15: 0.51643192 | U15: 83.050847 | V15: 0.45280824 | W15: 88.849227 | X15: 1.1654301 | Y15: 1 | Z15: 0.14084507 | AA15: 0.75117371 | AB15: 9.4430993 | AC15: 0.37447182 | AD15: 13.110453 | AE15: 0.98841278
C16: Rewe West | D16: 1 | E16: 0.98684211 | F16: 0.12305945 | G16: 89.655172 | H16: -0.4424566 | I16: 94.287986 | J16: -0.082654656 | K16: 1 | L16: 0.97368421 | M16: -1.19273 | N16: 89.37931 | O16: 0.25797143 | P16: 94.290027 | Q16: 0.50824596 | R16: 1 | S16: 0.96052632 | T16: 0.36917834 | U16: 81.517241 | V16: 0.90357332 | W16: 88.889692 | X16: 1.147953 | Y16: 1 | Z16: 0.95394737 | AA16: 1.1501325 | AB16: 63.586207 | AC16: 0.40629058 | AD16: 72.754392 | AE16: 0.074456044
C17: Wasgau | D17: 0.81538462 | E17: 0.97368421 | F17: -0.13157895 | G17: 0 | H17: 0 | I17: 0 | J17: 0 | K17: 0.81538462 | L17: 0.97368421 | M17: -0.13157895 | N17: 0 | O17: 0 | P17: 0 | Q17: 0 | R17: 0.70769231 | S17: 0.97058824 | T17: -0.30959752 | U17: 0 | V17: 0 | W17: 0 | X17: 0 | Y17: 0.81538462 | Z17: 0.97368421 | AA17: -0.13157895 | AB17: 0 | AC17: 0 | AD17: 0 | AE17: 0
C18: Edeka Konzern
C19: Edeka Hessenring (ZL) | D19: 1 | E19: 0.99186992 | F19: 0.096082779 | G19: 86.1615 | H19: 0.24564256 | I19: 99.201669 | J19: -0.047331934 | K19: 1 | L19: 0.99186992 | M19: 0.096082779 | N19: 90.358069 | O19: 4.4422117 | P19: 97.913511 | Q19: -1.4570003 | R19: 1 | S19: 0.99186992 | T19: 0.096082779 | U19: 79.24225 | V19: 0.36846384 | W19: 99.025214 | X19: 0.060946561 | Y19: 1 | Z19: 0.99186992 | AA19: 0.096082779 | AB19: 79.24225 | AC19: -6.6736076 | AD19: 99.025214 | AE19: -0.34529718
C20: Edeka Minden (ZL + Lüning) | D20: 1 | E20: 0.98614958 | F20: -0.54938696 | G20: 95.686696 | H20: -0.081137966 | I20: 99.127595 | J20: 4.8452753 | K20: 1 | L20: 0.99168975 | M20: 1.1188358 | N20: 93.008822 | O20: -1.1806792 | P20: 98.929908 | Q20: -0.35196441 | R20: 1 | S20: 0.96398892 | T20: 1.134268 | U20: 71.966315 | V20: 2.1884094 | W20: 92.891696 | X20: 6.7906947 | Y20: 0.98104956 | Z20: 0.97229917 | AA20: 1.1296383 | AB20: 72.419133 | AC20: -0.96039202 | AD20: 93.128348 | AE20: 0.95565546
C21: Edeka Nord (ZL) | D21: 1 | E21: 0.97278912 | F21: 2.0661456 | G21: 95.170146 | H21: 4.4428985 | I21: 97.635395 | J21: 8.7646166 | K21: 1 | L21: 0.91156463 | M21: -5.6520481 | N21: 84.039495 | O21: -4.7054651 | P21: 85.52418 | Q21: -7.2308988 | R21: 1 | S21: 0.81632653 | T21: -6.1333044 | U21: 78.900224 | V21: -7.7210112 | W21: 80.887989 | X21: -14.263114 | Y21: 1 | Z21: 0.93877551 | AA21: 11.962657 | AB21: 80.198323 | AC21: -12.301825 | AD21: 89.29163 | AE21: -6.3036509
C22: Edeka Nordbayern (ZL) | D22: 1 | E22: 0.99494949 | F22: 0.47534165 | G22: 98.465145 | H22: 0.75224224 | I22: 99.868452 | J22: 0.092158762 | K22: 1 | L22: 0.99494949 | M22: 0.47534165 | N22: 94.61784 | O22: -1.5211807 | P22: 98.761522 | Q22: -0.74287509 | R22: 0.99425287 | S22: 0.96969697 | T22: -0.08912656 | U22: 87.332352 | V22: 6.1528931 | W22: 96.608203 | X22: 3.0448954 | Y22: 1 | Z22: 0.98484848 | AA22: 0.93582888 | AB22: 87.974972 | AC22: 3.6770979 | AD22: 96.296202 | AE22: 2.3082054
C23: Edeka Rhein Ruhr (ZL) | D23: 1 | E23: 0.99380805 | F23: -0.27672929 | G23: 89.363722 | H23: -9.1062468 | I23: 96.903138 | J23: -2.9458748 | K23: 1 | L23: 0.9876161 | M23: -0.21099283 | N23: 91.112949 | O23: -0.43668053 | P23: 95.400096 | Q23: -2.9583691 | R23: 1 | S23: 0.98142415 | T23: -0.14525637 | U23: 65.281704 | V23: -12.54344 | W23: 79.851859 | X23: -13.667874 | Y23: 1 | Z23: 0.9752322 | AA23: 1.2903431 | AB23: 85.39882 | AC23: 18.464828 | AD23: 92.924594 | AE23: 11.076666
C24: Edeka Südbayern (ZL) | D24: 1 | E24: 0.97959184 | F24: 0.50155655 | G24: 93.151221 | H24: -2.3035918 | I24: 96.042591 | J24: -3.7679289 | K24: 1 | L24: 0.98979592 | M24: 1.5219647 | N24: 79.296595 | O24: 2.0653266 | P24: 98.823851 | Q24: 9.7402886 | R24: 1 | S24: 0.98979592 | T24: 1.5219647 | U24: 78.906812 | V24: 2.9127652 | W24: 96.830464 | X24: 7.6644614 | Y24: 1 | Z24: 0.97959184 | AA24: 2.1964718 | AB24: 72.713758 | AC24: -5.3832357 | AD24: 97.646316 | AE24: 5.3747282
C25: Edeka Südwest (ZL) | D25: 1 | E25: 0.98867925 | F25: 0.1377658 | G25: 92.363552 | H25: 0.92130336 | I25: 99.206718 | J25: 0.7820898 | K25: 1 | L25: 0.99622642 | M25: -0.059898173 | N25: 85.161171 | O25: -2.8234304 | P25: 97.420063 | Q25: 1.1121699 | R25: 1 | S25: 0.97358491 | T25: 0.85055406 | U25: 76.765782 | V25: 2.0321927 | W25: 95.350591 | X25: 3.0129152 | Y25: 1 | Z25: 0.98867925 | AA25: 0.1377658 | AB25: 86.475112 | AC25: -3.1585568 | AD25: 95.817574 | AE25: 0.62377563
C26: Markant Services International GmbH
C27: Bartels-Langness | D27: 1 | E27: 0.99019608 | F27: -0.0095183705 | G27: 0 | H27: 0 | I27: 0 | J27: 0 | K27: 1 | L27: 0.99019608 | M27: -0.0095183705 | N27: 0 | O27: 0 | P27: 0 | Q27: 0 | R27: 0.78723404 | S27: 0.97647059 | T27: -1.1901505 | U27: 0 | V27: 0 | W27: 0 | X27: 0 | Y27: 0.76595745 | Z27: 0.96511628 | AA27: 1.2175103 | AB27: 0 | AC27: 0 | AD27: 0 | AE27: 0
C28: Bünting (ZL) | D28: 1 | E28: 0.9924812 | F28: 0.10282116 | G28: 0 | H28: 0 | I28: 0 | J28: 0 | K28: 1 | L28: 0.9924812 | M28: 0.10282116 | N28: 0 | O28: 0 | P28: 0 | Q28: 0 | R28: 1 | S28: 0.96240602 | T28: 0.51410578 | U28: 0 | V28: 0 | W28: 0 | X28: 0 | Y28: 1 | Z28: 0.9924812 | AA28: 0.10282116 | AB28: 0 | AC28: 0 | AD28: 0 | AE28: 0
C29: Globus | D29: 1 | E29: 0.98305085 | F29: -0.055570992 | G29: 0 | H29: 0 | I29: 0 | J29: 0 | K29: 1 | L29: 0.98305085 | M29: -0.055570992 | N29: 0 | O29: 0 | P29: 0 | Q29: 0 | R29: 1 | S29: 0.98305085 | T29: -0.055570992 | U29: 0 | V29: 0 | W29: 0 | X29: 0 | Y29: 1 | Z29: 0.96610169 | AA29: -0.11114198 | AB29: 0 | AC29: 0 | AD29: 0 | AE29: 0
C30: Kaes | D30: 1 | E30: 0.97297297 | F30: 0.15444015 | G30: 0 | H30: 0 | I30: 0 | J30: 0 | K30: 1 | L30: 0.97297297 | M30: 0.15444015 | N30: 0 | O30: 0 | P30: 0 | Q30: 0 | R30: 1 | S30: 0.97297297 | T30: 0.15444015 | U30: 0 | V30: 0 | W30: 0 | X30: 0 | Y30: 1 | Z30: 0.97297297 | AA30: 0.15444015 | AB30: 0 | AC30: 0 | AD30: 0 | AE30: 0
C31: Kaufland | D31: 1 | E31: 0.9962963 | F31: -0.034799901 | G31: 0 | H31: 0 | I31: 0 | J31: 0 | K31: 1 | L31: 0.99814815 | M31: 0.15038528 | N31: 0 | O31: 0 | P31: 0 | Q31: 0 | R31: 1 | S31: 0.9962963 | T31: 1.1396967 | U31: 0 | V31: 0 | W31: 0 | X31: 0 | Y31: 0.65394737 | Z31: 0.9921875 | AA31: 0.41779077 | AB31: 0 | AC31: 0 | AD31: 0 | AE31: 0

Sheet Händler -> Produkte Märkte
D3: Top (Hero)
D4: 1 | H4: 2 | L4: 5 | P4: 10
D5: Kühne Dressing Joghurt 0,5l | H5: Kühne Dressing Kräuterwürzig 0,5l | L5: Kühne Dressing Jogh.-Kräuter leicht 0,5l | P5: Kühne Dressing French 0,5l
D6: MT Märkte - gesamt | E6: MT Märkte – Listung | F6: MT Märkte - besucht | G6: Circana Märkte | H6: MT Märkte - gesamt | I6: MT Märkte – Listung | J6: MT Märkte - besucht | K6: Circana Märkte | L6: MT Märkte - gesamt | M6: MT Märkte – Listung | N6: MT Märkte - besucht | O6: Circana Märkte | P6: MT Märkte - gesamt | Q6: MT Märkte – Listung | R6: MT Märkte - besucht | S6: Circana Märkte
C7: Rewe Gruppe
C8: Hit | D8: 91 | E8: 91 | F8: 83 | G8: 0 | H8: 91 | I8: 91 | J8: 83 | K8: 0 | L8: 91 | M8: 91 | N8: 83 | O8: 0 | P8: 91 | Q8: 91 | R8: 83 | S8: 0
C9: mein real | D9: 62 | E9: 62 | F9: 53 | G9: 62 | H9: 62 | I9: 62 | J9: 53 | K9: 62 | L9: 62 | M9: 62 | N9: 53 | O9: 62 | P9: 62 | Q9: 62 | R9: 53 | S9: 62
C10: Rewe Dortmund | D10: 316 | E10: 316 | F10: 198 | G10: 0 | H10: 316 | I10: 316 | J10: 198 | K10: 0 | L10: 316 | M10: 316 | N10: 198 | O10: 0 | P10: 316 | Q10: 316 | R10: 198 | S10: 0
C11: Rewe Mitte | D11: 369 | E11: 369 | F11: 97 | G11: 455 | H11: 369 | I11: 369 | J11: 97 | K11: 455 | L11: 369 | M11: 369 | N11: 97 | O11: 455 | P11: 369 | Q11: 369 | R11: 97 | S11: 455
C12: Rewe Nord | D12: 517 | E12: 517 | F12: 93 | G12: 597 | H12: 517 | I12: 517 | J12: 93 | K12: 597 | L12: 517 | M12: 517 | N12: 93 | O12: 597 | P12: 517 | Q12: 517 | R12: 93 | S12: 597
C13: Rewe Ost | D13: 459 | E13: 459 | F13: 126 | G13: 585 | H13: 459 | I13: 459 | J13: 126 | K13: 585 | L13: 459 | M13: 459 | N13: 126 | O13: 585 | P13: 459 | Q13: 459 | R13: 126 | S13: 585
C14: Rewe Süd | D14: 288 | E14: 288 | F14: 114 | G14: 583 | H14: 288 | I14: 288 | J14: 114 | K14: 583 | L14: 288 | M14: 288 | N14: 114 | O14: 583 | P14: 288 | Q14: 288 | R14: 114 | S14: 583
C15: Rewe Südwest | D15: 378 | E15: 378 | F15: 71 | G15: 411 | H15: 378 | I15: 378 | J15: 71 | K15: 411 | L15: 378 | M15: 378 | N15: 71 | O15: 411 | P15: 378 | Q15: 378 | R15: 71 | S15: 411
C16: Rewe West | D16: 331 | E16: 331 | F16: 152 | G16: 721 | H16: 331 | I16: 331 | J16: 152 | K16: 721 | L16: 331 | M16: 331 | N16: 152 | O16: 721 | P16: 331 | Q16: 331 | R16: 152 | S16: 721
C17: Wasgau | D17: 65 | E17: 53 | F17: 38 | G17: 0 | H17: 65 | I17: 53 | J17: 38 | K17: 0 | L17: 65 | M17: 46 | N17: 34 | O17: 0 | P17: 65 | Q17: 53 | R17: 38 | S17: 0
C18: Edeka Konzern
C19: Edeka Hessenring (ZL) | D19: 229 | E19: 229 | F19: 123 | G19: 340 | H19: 229 | I19: 229 | J19: 123 | K19: 340 | L19: 229 | M19: 229 | N19: 123 | O19: 340 | P19: 229 | Q19: 229 | R19: 123 | S19: 340
C20: Edeka Minden (ZL + Lüning) | D20: 686 | E20: 686 | F20: 361 | G20: 1015 | H20: 686 | I20: 686 | J20: 361 | K20: 1015 | L20: 686 | M20: 686 | N20: 361 | O20: 1015 | P20: 686 | Q20: 673 | R20: 361 | S20: 1015
C21: Edeka Nord (ZL) | D21: 344 | E21: 344 | F21: 147 | G21: 460 | H21: 344 | I21: 344 | J21: 147 | K21: 460 | L21: 344 | M21: 344 | N21: 147 | O21: 460 | P21: 344 | Q21: 344 | R21: 147 | S21: 460
C22: Edeka Nordbayern (ZL) | D22: 348 | E22: 348 | F22: 198 | G22: 511 | H22: 348 | I22: 348 | J22: 198 | K22: 511 | L22: 348 | M22: 346 | N22: 198 | O22: 511 | P22: 348 | Q22: 348 | R22: 198 | S22: 511
C23: Edeka Rhein Ruhr (ZL) | D23: 450 | E23: 450 | F23: 323 | G23: 565 | H23: 450 | I23: 450 | J23: 323 | K23: 565 | L23: 450 | M23: 450 | N23: 323 | O23: 565 | P23: 450 | Q23: 450 | R23: 323 | S23: 565
C24: Edeka Südbayern (ZL) | D24: 430 | E24: 430 | F24: 98 | G24: 890 | H24: 430 | I24: 430 | J24: 98 | K24: 890 | L24: 430 | M24: 430 | N24: 98 | O24: 890 | P24: 430 | Q24: 430 | R24: 98 | S24: 890
C25: Edeka Südwest (ZL) | D25: 594 | E25: 594 | F25: 265 | G25: 880 | H25: 594 | I25: 594 | J25: 265 | K25: 880 | L25: 594 | M25: 594 | N25: 265 | O25: 880 | P25: 594 | Q25: 594 | R25: 265 | S25: 880
C26: Markant Services International GmbH
C27: Bartels-Langness | D27: 141 | E27: 141 | F27: 102 | G27: 0 | H27: 141 | I27: 141 | J27: 102 | K27: 0 | L27: 141 | M27: 111 | N27: 85 | O27: 0 | P27: 141 | Q27: 108 | R27: 86 | S27: 0
C28: Bünting (ZL) | D28: 204 | E28: 204 | F28: 133 | G28: 0 | H28: 204 | I28: 204 | J28: 133 | K28: 0 | L28: 204 | M28: 204 | N28: 133 | O28: 0 | P28: 204 | Q28: 204 | R28: 133 | S28: 0
C29: Globus | D29: 62 | E29: 62 | F29: 59 | G29: 0 | H29: 62 | I29: 62 | J29: 59 | K29: 0 | L29: 62 | M29: 62 | N29: 59 | O29: 0 | P29: 62 | Q29: 62 | R29: 59 | S29: 0
C30: Kaes | D30: 40 | E30: 40 | F30: 37 | G30: 0 | H30: 40 | I30: 40 | J30: 37 | K30: 0 | L30: 40 | M30: 40 | N30: 37 | O30: 0 | P30: 40 | Q30: 40 | R30: 37 | S30: 0
C31: Kaufland | D31: 760 | E31: 760 | F31: 540 | G31: 0 | H31: 760 | I31: 760 | J31: 540 | K31: 0 | L31: 760 | M31: 760 | N31: 540 | O31: 0 | P31: 760 | Q31: 497 | R31: 384 | S31: 0

Sheet Daten
A1: Kundenhierarchie 1 | B1: Händler | C1: Kategorie | D1: Gruppe | E1: Name | F1: Sortimentsranking | G1: SKU Type | H1: Listung % | I1: MT Distri % (besucht) | J1: IRi nDistr (ohne Promo) | K1: IRi nDistr VÄ vs. VJ | L1: Anzahl Stores – Listung | M1: Anzahl Stores - gesamt | N1: Anzahl Stores - besucht gesamt | O1: Anzahl Stores - besucht Distribution | P1: Circana - Anzahl Märkte | Q1: Cir gewDistr (ohne Promo) | R1: Cir gewDistr VÄ vs. VJ | S1: MT Distri % (besucht) VP | T1: MT Distri % VÄ
A2: Edeka Konzern | B2: Edeka Hessenring (ZL) | C2: Dressing | D2: Dressing 500ml | E2: Kühne Dressing 1000 Islands 0,5l | F2: 15 | G2: Ergänzung | H2: 0 | I2: 0 | J2: 12.28957 | K2: 12.28957 | L2: 0 | M2: 229 | N2: 1 | O2: 0 | P2: 340 | Q2: 26.462717 | R2: 26.462717 | S2: =V2 -> 0 | T2: =(Tabelle1[[#This Row],[MT Distri % (besucht)]]-Tabelle1[[#This Row],[MT Distri % (besucht) VP]])*100 -> 0 | U2: =Tabelle1[[#This Row],[Kundenhierarchie 1]]&Tabelle1[[#This Row],[Händler]]&Tabelle1[[#This Row],[Kategorie]]&Tabelle1[[#This Row],[Gruppe]]&Tabelle1[[#This Row],[Name]] -> Edeka KonzernEdeka Hessenring (ZL)DressingDressing 500mlKühne Dressing 1000 Islands 0,5l | V2: =_xlfn.XLOOKUP(U2,'Daten Vor-Quartal'!U:U,'Daten Vor-Quartal'!I:I,0) -> 0 | AB2: Kühne Dressing 1000 Islands 0,5l | AC2: =VLOOKUP(AB2,$AE$2:$AE$168,1,0) -> Kühne Dressing 1000 Islands 0,5l | AE2: Kühne Dressing 1000 Islands 0,5l
A3: Edeka Konzern | B3: Edeka Hessenring (ZL) | C3: Dressing | D3: Dressing 500ml | E3: Kühne Dressing American 0,5l | F3: 19 | G3: Ergänzung | H3: 0 | I3: 0 | J3: 12.28957 | K3: 12.28957 | L3: 0 | M3: 229 | N3: 1 | O3: 0 | P3: 340 | Q3: 26.462717 | R3: 26.462717 | S3: =V3 -> 0 | T3: =(Tabelle1[[#This Row],[MT Distri % (besucht)]]-Tabelle1[[#This Row],[MT Distri % (besucht) VP]])*100 -> 0 | U3: =Tabelle1[[#This Row],[Kundenhierarchie 1]]&Tabelle1[[#This Row],[Händler]]&Tabelle1[[#This Row],[Kategorie]]&Tabelle1[[#This Row],[Gruppe]]&Tabelle1[[#This Row],[Name]] -> Edeka KonzernEdeka Hessenring (ZL)DressingDressing 500mlKühne Dressing American 0,5l | V3: =_xlfn.XLOOKUP(U3,'Daten Vor-Quartal'!U:U,'Daten Vor-Quartal'!I:I,0) -> 0 | AB3: Kühne Dressing American 0,5l | AC3: =VLOOKUP(AB3,$AE$2:$AE$168,1,0) -> Kühne Dressing American 0,5l | AE3: Kühne Dressing American 0,5l
A4: Edeka Konzern | B4: Edeka Hessenring (ZL) | C4: Dressing | D4: Dressing 500ml | E4: Kühne Dressing Balsamico 0,5l | F4: 18 | G4: Ergänzung | H4: 0 | I4: 0 | J4: 0 | K4: 0 | L4: 0 | M4: 229 | N4: 1 | O4: 0 | P4: 340 | Q4: 0 | R4: 0 | S4: =V4 -> 0 | T4: =(Tabelle1[[#This Row],[MT Distri % (besucht)]]-Tabelle1[[#This Row],[MT Distri % (besucht) VP]])*100 -> 0 | U4: =Tabelle1[[#This Row],[Kundenhierarchie 1]]&Tabelle1[[#This Row],[Händler]]&Tabelle1[[#This Row],[Kategorie]]&Tabelle1[[#This Row],[Gruppe]]&Tabelle1[[#This Row],[Name]] -> Edeka KonzernEdeka Hessenring (ZL)DressingDressing 500mlKühne Dressing Balsamico 0,5l | V4: =_xlfn.XLOOKUP(U4,'Daten Vor-Quartal'!U:U,'Daten Vor-Quartal'!I:I,0) -> 0 | AB4: Kühne Dressing Balsamico 0,5l | AC4: =VLOOKUP(AB4,$AE$2:$AE$168,1,0) -> Kühne Dressing Balsamico 0,5l | AE4: Kühne Dressing Balsamico 0,5l
A5: Edeka Konzern | B5: Edeka Hessenring (ZL) | C5: Dressing | D5: Dressing 500ml | E5: Kühne Dressing Caesar 0,5l | F5: 13 | G5: Ergänzung | H5: 0 | I5: 0 | J5: 0 | K5: 0 | L5: 0 | M5: 229 | N5: 1 | O5: 0 | P5: 340 | Q5: 0 | R5: 0 | S5: =V5 -> 0 | T5: =(Tabelle1[[#This Row],[MT Distri % (besucht)]]-Tabelle1[[#This Row],[MT Distri % (besucht) VP]])*100 -> 0 | U5: =Tabelle1[[#This Row],[Kundenhierarchie 1]]&Tabelle1[[#This Row],[Händler]]&Tabelle1[[#This Row],[Kategorie]]&Tabelle1[[#This Row],[Gruppe]]&Tabelle1[[#This Row],[Name]] -> Edeka KonzernEdeka Hessenring (ZL)DressingDressing 500mlKühne Dressing Caesar 0,5l | V5: =_xlfn.XLOOKUP(U5,'Daten Vor-Quartal'!U:U,'Daten Vor-Quartal'!I:I,0) -> 0 | AB5: Kühne Dressing Caesar 0,5l | AC5: =VLOOKUP(AB5,$AE$2:$AE$168,1,0) -> Kühne Dressing Caesar 0,5l | AE5: Kühne Dressing Caesar 0,5l
A6: Edeka Konzern | B6: Edeka Hessenring (ZL) | C6: Dressing | D6: Dressing 500ml | E6: Kühne Dressing French 0,5l | F6: 10 | G6: Top (Hero) | H6: 1 | I6: 0.99186992 | J6: 79.24225 | K6: -6.6736076 | L6: 229 | M6: 229 | N6: 123 | O6: 122 | P6: 340 | Q6: 99.025214 | R6: -0.34529718 | S6: =V6 -> 0.99090909 | T6: =(Tabelle1[[#This Row],[MT Distri % (besucht)]]-Tabelle1[[#This Row],[MT Distri % (besucht) VP]])*100 -> 0.096082779 | U6: =Tabelle1[[#This Row],[Kundenhierarchie 1]]&Tabelle1[[#This Row],[Händler]]&Tabelle1[[#This Row],[Kategorie]]&Tabelle1[[#This Row],[Gruppe]]&Tabelle1[[#This Row],[Name]] -> Edeka KonzernEdeka Hessenring (ZL)DressingDressing 500mlKühne Dressing French 0,5l | V6: =_xlfn.XLOOKUP(U6,'Daten Vor-Quartal'!U:U,'Daten Vor-Quartal'!I:I,0) -> 0.99090909 | AB6: Kühne Dressing French 0,5l | AC6: =VLOOKUP(AB6,$AE$2:$AE$168,1,0) -> Kühne Dressing French 0,5l | AE6: Kühne Dressing French 0,5l
A7: Edeka Konzern | B7: Edeka Hessenring (ZL) | C7: Dressing | D7: Dressing 500ml | E7: Kühne Dressing Gartenkräuter 0,5l | F7: 16 | G7: Ergänzung | H7: 1 | I7: 0.99186992 | J7: 79.24225 | K7: 0.36846384 | L7: 229 | M7: 229 | N7: 123 | O7: 122 | P7: 340 | Q7: 99.025214 | R7: 0.060946561 | S7: =V7 -> 0.98181818 | T7: =(Tabelle1[[#This Row],[MT Distri % (besucht)]]-Tabelle1[[#This Row],[MT Distri % (besucht) VP]])*100 -> 1.0051737 | U7: =Tabelle1[[#This Row],[Kundenhierarchie 1]]&Tabelle1[[#This Row],[Händler]]&Tabelle1[[#This Row],[Kategorie]]&Tabelle1[[#This Row],[Gruppe]]&Tabelle1[[#This Row],[Name]] -> Edeka KonzernEdeka Hessenring (ZL)DressingDressing 500mlKühne Dressing Gartenkräuter 0,5l | V7: =_xlfn.XLOOKUP(U7,'Daten Vor-Quartal'!U:U,'Daten Vor-Quartal'!I:I,0) -> 0.98181818 | AB7: Kühne Dressing Gartenkräuter 0,5l | AC7: =VLOOKUP(AB7,$AE$2:$AE$168,1,0) -> Kühne Dressing Gartenkräuter 0,5l | AE7: Kühne Dressing Gartenkräuter 0,5l
A8: Edeka Konzern | B8: Edeka Hessenring (ZL) | C8: Dressing | D8: Dressing 500ml | E8: Kühne Dressing Jogh.-Kräuter leicht 0,5l | F8: 5 | G8: Top (Hero) | H8: 1 | I8: 0.99186992 | J8: 79.24225 | K8: 0.36846384 | L8: 229 | M8: 229 | N8: 123 | O8: 122 | P8: 340 | Q8: 99.025214 | R8: 0.060946561 | S8: =V8 -> 0.99090909 | T8: =(Tabelle1[[#This Row],[MT Distri % (besucht)]]-Tabelle1[[#This Row],[MT Distri % (besucht) VP]])*100 -> 0.096082779 | U8: =Tabelle1[[#This Row],[Kundenhierarchie 1]]&Tabelle1[[#This Row],[Händler]]&Tabelle1[[#This Row],[Kategorie]]&Tabelle1[[#This Row],[Gruppe]]&Tabelle1[[#This Row],[Name]] -> Edeka KonzernEdeka Hessenring (ZL)DressingDressing 500mlKühne Dressing Jogh.-Kräuter leicht 0,5l | V8: =_xlfn.XLOOKUP(U8,'Daten Vor-Quartal'!U:U,'Daten Vor-Quartal'!I:I,0) -> 0.99090909 | AB8: Kühne Dressing Jogh.-Kräuter leicht 0,5l | AC8: =VLOOKUP(AB8,$AE$2:$AE$168,1,0) -> Kühne Dressing Jogh.-Kräuter leicht 0,5l | AE8: Kühne Dressing Jogh.-Kräuter leicht 0,5l
A9: Edeka Konzern | B9: Edeka Hessenring (ZL) | C9: Dressing | D9: Dressing 500ml | E9: Kühne Dressing Joghurt 0,5l | F9: 1 | G9: Top (Hero) | H9: 1 | I9: 0.99186992 | J9: 86.1615 | K9: 0.24564256 | L9: 229 | M9: 229 | N9: 123 | O9: 122 | P9: 340 | Q9: 99.201669 | R9: -0.047331934 | S9: =V9 -> 0.99090909 | T9: =(Tabelle1[[#This Row],[MT Distri % (besucht)]]-Tabelle1[[#This Row],[MT Distri % (besucht) VP]])*100 -> 0.096082779 | U9: =Tabelle1[[#This Row],[Kundenhierarchie 1]]&Tabelle1[[#This Row],[Händler]]&Tabelle1[[#This Row],[Kategorie]]&Tabelle1[[#This Row],[Gruppe]]&Tabelle1[[#This Row],[Name]] -> Edeka KonzernEdeka Hessenring (ZL)DressingDressing 500mlKühne Dressing Joghurt 0,5l | V9: =_xlfn.XLOOKUP(U9,'Daten Vor-Quartal'!U:U,'Daten Vor-Quartal'!I:I,0) -> 0.99090909 | AB9: Kühne Dressing Joghurt 0,5l | AC9: =VLOOKUP(AB9,$AE$2:$AE$168,1,0) -> Kühne Dressing Joghurt 0,5l | AE9: Kühne Dressing Joghurt 0,5l
A10: Edeka Konzern | B10: Edeka Hessenring (ZL) | C10: Dressing | D10: Dressing 500ml | E10: Kühne Dressing Kräuterwürzig 0,5l | F10: 2 | G10: Top (Hero) | H10: 1 | I10: 0.99186992 | J10: 90.358069 | K10: 4.4422117 | L10: 229 | M10: 229 | N10: 123 | O10: 122 | P10: 340 | Q10: 97.913511 | R10: -1.4570003 | S10: =V10 -> 0.99090909 | T10: =(Tabelle1[[#This Row],[MT Distri % (besucht)]]-Tabelle1[[#This Row],[MT Distri % (besucht) VP]])*100 -> 0.096082779 | U10: =Tabelle1[[#This Row],[Kundenhierarchie 1]]&Tabelle1[[#This Row],[Händler]]&Tabelle1[[#This Row],[Kategorie]]&Tabelle1[[#This Row],[Gruppe]]&Tabelle1[[#This Row],[Name]] -> Edeka KonzernEdeka Hessenring (ZL)DressingDressing 500mlKühne Dressing Kräuterwürzig 0,5l | V10: =_xlfn.XLOOKUP(U10,'Daten Vor-Quartal'!U:U,'Daten Vor-Quartal'!I:I,0) -> 0.99090909 | AB10: Kühne Dressing Kräuterwürzig 0,5l | AC10: =VLOOKUP(AB10,$AE$2:$AE$168,1,0) -> Kühne Dressing Kräuterwürzig 0,5l | AE10: Kühne Dressing Kräuterwürzig 0,5l
A11: Edeka Konzern | B11: Edeka Hessenring (ZL) | C11: Dressing | D11: Dressing 1l | E11: Kühne Dressing 1000 Islands, 1l Fl. | F11: 26 | G11: Completion | H11: 0 | I11: 0 | J11: 0 | K11: 0 | L11: 0 | M11: 229 | N11: 1 | O11: 0 | P11: 340 | Q11: 0 | R11: 0 | S11: =V11 -> 0 | T11: =(Tabelle1[[#This Row],[MT Distri % (besucht)]]-Tabelle1[[#This Row],[MT Distri % (besucht) VP]])*100 -> 0 | U11: =Tabelle1[[#This Row],[Kundenhierarchie 1]]&Tabelle1[[#This Row],[Händler]]&Tabelle1[[#This Row],[Kategorie]]&Tabelle1[[#This Row],[Gruppe]]&Tabelle1[[#This Row],[Name]] -> Edeka KonzernEdeka Hessenring (ZL)DressingDressing 1lKühne Dressing 1000 Islands, 1l Fl. | V11: =_xlfn.XLOOKUP(U11,'Daten Vor-Quartal'!U:U,'Daten Vor-Quartal'!I:I,0) -> 0 | AB11: Kühne Dressing 1000 Islands, 1l Fl. | AC11: =VLOOKUP(AB11,$AE$2:$AE$168,1,0) -> Kühne Dressing 1000 Islands, 1l Fl. | AE11: Kühne Dressing 1000 Islands, 1l Fl.
A12: Edeka Konzern | B12: Edeka Hessenring (ZL) | C12: Dressing | D12: Dressing 1l | E12: Kühne Dressing Balsamico, 1l Fl. | F12: 27 | G12: Completion | H12: 0 | I12: 0 | J12: 0 | K12: 0 | L12: 0 | M12: 229 | N12: 1 | O12: 0 | P12: 0 | Q12: 0 | R12: 0 | S12: =V12 -> 0 | T12: =(Tabelle1[[#This Row],[MT Distri % (besucht)]]-Tabelle1[[#This Row],[MT Distri % (besucht) VP]])*100 -> 0 | U12: =Tabelle1[[#This Row],[Kundenhierarchie 1]]&Tabelle1[[#This Row],[Händler]]&Tabelle1[[#This Row],[Kategorie]]&Tabelle1[[#This Row],[Gruppe]]&Tabelle1[[#This Row],[Name]] -> Edeka KonzernEdeka Hessenring (ZL)DressingDressing 1lKühne Dressing Balsamico, 1l Fl. | V12: =_xlfn.XLOOKUP(U12,'Daten Vor-Quartal'!U:U,'Daten Vor-Quartal'!I:I,0) -> 0 | AB12: Kühne Dressing Balsamico, 1l Fl. | AC12: =VLOOKUP(AB12,$AE$2:$AE$168,1,0) -> Kühne Dressing Balsamico, 1l Fl. | AE12: Kühne Dressing Balsamico, 1l Fl.
A13: Edeka Konzern | B13: Edeka Hessenring (ZL) | C13: Dressing | D13: Dressing 1l | E13: Kühne Dressing French 1l Fl. | F13: 25 | G13: Completion | H13: 0 | I13: 0 | J13: 0 | K13: 0 | L13: 0 | M13: 229 | N13: 1 | O13: 0 | P13: 340 | Q13: 0 | R13: 0 | S13: =V13 -> 0 | T13: =(Tabelle1[[#This Row],[MT Distri % (besucht)]]-Tabelle1[[#This Row],[MT Distri % (besucht) VP]])*100 -> 0 | U13: =Tabelle1[[#This Row],[Kundenhierarchie 1]]&Tabelle1[[#This Row],[Händler]]&Tabelle1[[#This Row],[Kategorie]]&Tabelle1[[#This Row],[Gruppe]]&Tabelle1[[#This Row],[Name]] -> Edeka KonzernEdeka Hessenring (ZL)DressingDressing 1lKühne Dressing French 1l Fl. | V13: =_xlfn.XLOOKUP(U13,'Daten Vor-Quartal'!U:U,'Daten Vor-Quartal'!I:I,0) -> 0 | AB13: Kühne Dressing French 1l Fl. | AC13: =VLOOKUP(AB13,$AE$2:$AE$168,1,0) -> Kühne Dressing French 1l Fl. | AE13: Kühne Dressing French 1l Fl.
... A168: Edeka Konzern | B168: Edeka Hessenring (ZL) | C168: Würzsaucen | D168: Würzsaucen Standard | E168: Würzsauce Curry, 250ml | F168: 3 | G168: Top (Hero) | H168: 0 | I168: 0 | J168: 42.341092 | K168: -1.6320549 | L168: 0 | M168: 229 | N168: 1 | O168: 0 | P168: 340 | Q168: 65.684133 | R168: -4.9226411 | S168: =V168 -> 0 | T168: =(Tabelle1[[#This Row],[MT Distri % (besucht)]]-Tabelle1[[#This Row],[MT Distri % (besucht) VP]])*100 -> 0 | U168: =Tabelle1[[#This Row],[Kundenhierarchie 1]]&Tabelle1[[#This Row],[Händler]]&Tabelle1[[#This Row],[Kategorie]]&Tabelle1[[#This Row],[Gruppe]]&Tabelle1[[#This Row],[Name]] -> Edeka KonzernEdeka Hessenring (ZL)WürzsaucenWürzsaucen StandardWürzsauce Curry, 250ml | V168: =_xlfn.XLOOKUP(U168,'Daten Vor-Quartal'!U:U,'Daten Vor-Quartal'!I:I,0) -> 0 | AB168: Würzsauce Mexico, 250ml | AC168: =VLOOKUP(AB168,$AE$2:$AE$168,1,0) -> #N/A | AE168: Würzsauce Unschuldsengel, 250ml
A169: Edeka Konzern | B169: Edeka Hessenring (ZL) | C169: Würzsaucen | D169: Würzsaucen Standard | E169: Würzsauce Hot Chili, 250ml | F169: 7 | G169: Top (Hero) | H169: 0 | I169: 0 | J169: 55.510812 | K169: -0.65637633 | L169: 0 | M169: 229 | N169: 1 | O169: 0 | P169: 340 | Q169: 80.56109 | R169: -2.0398856 | S169: =V169 -> 0 | T169: =(Tabelle1[[#This Row],[MT Distri % (besucht)]]-Tabelle1[[#This Row],[MT Distri % (besucht) VP]])*100 -> 0 | U169: =Tabelle1[[#This Row],[Kundenhierarchie 1]]&Tabelle1[[#This Row],[Händler]]&Tabelle1[[#This Row],[Kategorie]]&Tabelle1[[#This Row],[Gruppe]]&Tabelle1[[#This Row],[Name]] -> Edeka KonzernEdeka Hessenring (ZL)WürzsaucenWürzsaucen StandardWürzsauce Hot Chili, 250ml | V169: =_xlfn.XLOOKUP(U169,'Daten Vor-Quartal'!U:U,'Daten Vor-Quartal'!I:I,0) -> 0 | AB169: Würzsauce Paprikasauce Ungar. Art, 250ml | AC169: =VLOOKUP(AB169,$AE$2:$AE$168,1,0) -> Würzsauce Paprikasauce Ungar. Art, 250ml
A170: Edeka Konzern | B170: Edeka Hessenring (ZL) | C170: Würzsaucen | D170: Würzsaucen Standard | E170: Würzsauce Knoblauch, 250ml | F170: 1 | G170: Top (Hero) | H170: 0 | I170: 0 | J170: 50.062181 | K170: -2.5366498 | L170: 0 | M170: 229 | N170: 1 | O170: 0 | P170: 340 | Q170: 79.386408 | R170: 8.327888 | S170: =V170 -> 0 | T170: =(Tabelle1[[#This Row],[MT Distri % (besucht)]]-Tabelle1[[#This Row],[MT Distri % (besucht) VP]])*100 -> 0 | U170: =Tabelle1[[#This Row],[Kundenhierarchie 1]]&Tabelle1[[#This Row],[Händler]]&Tabelle1[[#This Row],[Kategorie]]&Tabelle1[[#This Row],[Gruppe]]&Tabelle1[[#This Row],[Name]] -> Edeka KonzernEdeka Hessenring (ZL)WürzsaucenWürzsaucen StandardWürzsauce Knoblauch, 250ml | V170: =_xlfn.XLOOKUP(U170,'Daten Vor-Quartal'!U:U,'Daten Vor-Quartal'!I:I,0) -> 0 | AB170: Würzsauce Schaschlik, 250ml | AC170: =VLOOKUP(AB170,$AE$2:$AE$168,1,0) -> Würzsauce Schaschlik, 250ml
A171: Edeka Konzern | B171: Edeka Hessenring (ZL) | C171: Würzsaucen | D171: Würzsaucen Standard | E171: Würzsauce Mexico, 250ml | F171: 5 | G171: Top (Hero) | H171: 1 | I171: 0.99186992 | J171: 86.1615 | K171: 0.24564256 | L171: 229 | M171: 229 | N171: 123 | O171: 122 | P171: 340 | Q171: 99.223697 | R171: 0.24695229 | S171: =V171 -> 0.99090909 | T171: =(Tabelle1[[#This Row],[MT Distri % (besucht)]]-Tabelle1[[#This Row],[MT Distri % (besucht) VP]])*100 -> 0.096082779 | U171: =Tabelle1[[#This Row],[Kundenhierarchie 1]]&Tabelle1[[#This Row],[Händler]]&Tabelle1[[#This Row],[Kategorie]]&Tabelle1[[#This Row],[Gruppe]]&Tabelle1[[#This Row],[Name]] -> Edeka KonzernEdeka Hessenring (ZL)WürzsaucenWürzsaucen StandardWürzsauce Mexico, 250ml | V171: =_xlfn.XLOOKUP(U171,'Daten Vor-Quartal'!U:U,'Daten Vor-Quartal'!I:I,0) -> 0.99090909 | AB171: Würzsauce Steak, 250ml | AC171: =VLOOKUP(AB171,$AE$2:$AE$168,1,0) -> Würzsauce Steak, 250ml
A172: Edeka Konzern | B172: Edeka Hessenring (ZL) | C172: Würzsaucen | D172: Würzsaucen Standard | E172: Würzsauce Paprikasauce Ungar. Art, 250ml | F172: 14 | G172: Ergänzung | H172: 0 | I172: 0 | J172: 0 | K172: 0 | L172: 0 | M172: 229 | N172: 1 | O172: 0 | P172: 340 | Q172: 0 | R172: 0 | S172: =V172 -> 0 | T172: =(Tabelle1[[#This Row],[MT Distri % (besucht)]]-Tabelle1[[#This Row],[MT Distri % (besucht) VP]])*100 -> 0 | U172: =Tabelle1[[#This Row],[Kundenhierarchie 1]]&Tabelle1[[#This Row],[Händler]]&Tabelle1[[#This Row],[Kategorie]]&Tabelle1[[#This Row],[Gruppe]]&Tabelle1[[#This Row],[Name]] -> Edeka KonzernEdeka Hessenring (ZL)WürzsaucenWürzsaucen StandardWürzsauce Paprikasauce Ungar. Art, 250ml | V172: =_xlfn.XLOOKUP(U172,'Daten Vor-Quartal'!U:U,'Daten Vor-Quartal'!I:I,0) -> 0 | AB172: Würzsauce Tzatziki, 250ml | AC172: =VLOOKUP(AB172,$AE$2:$AE$168,1,0) -> Würzsauce Tzatziki, 250ml
A173: Edeka Konzern | B173: Edeka Hessenring (ZL) | C173: Würzsaucen | D173: Würzsaucen Standard | E173: Würzsauce Schaschlik, 250ml | F173: 12 | G173: Ergänzung | H173: 1 | I173: 0.98373984 | J173: 96.828731 | K173: 6.0368476 | L173: 229 | M173: 229 | N173: 123 | O173: 121 | P173: 340 | Q173: 99.669876 | R173: 7.1224531 | S173: =V173 -> 0.99090909 | T173: =(Tabelle1[[#This Row],[MT Distri % (besucht)]]-Tabelle1[[#This Row],[MT Distri % (besucht) VP]])*100 -> -0.71692535 | U173: =Tabelle1[[#This Row],[Kundenhierarchie 1]]&Tabelle1[[#This Row],[Händler]]&Tabelle1[[#This Row],[Kategorie]]&Tabelle1[[#This Row],[Gruppe]]&Tabelle1[[#This Row],[Name]] -> Edeka KonzernEdeka Hessenring (ZL)WürzsaucenWürzsaucen StandardWürzsauce Schaschlik, 250ml | V173: =_xlfn.XLOOKUP(U173,'Daten Vor-Quartal'!U:U,'Daten Vor-Quartal'!I:I,0) -> 0.99090909 | AB173: Würzsauce Unschuldsengel, 250ml | AC173: =VLOOKUP(AB173,$AE$2:$AE$168,1,0) -> Würzsauce Unschuldsengel, 250ml
A174: Edeka Konzern | B174: Edeka Hessenring (ZL) | C174: Würzsaucen | D174: Würzsaucen Standard | E174: Würzsauce Steak, 250ml | F174: 2 | G174: Top (Hero) | H174: 1 | I174: 0.99186992 | J174: 86.1615 | K174: -6.7964288 | L174: 229 | M174: 229 | N174: 123 | O174: 122 | P174: 340 | Q174: 99.411186 | R174: -0.2459555 | S174: =V174 -> 0.99090909 | T174: =(Tabelle1[[#This Row],[MT Distri % (besucht)]]-Tabelle1[[#This Row],[MT Distri % (besucht) VP]])*100 -> 0.096082779 | U174: =Tabelle1[[#This Row],[Kundenhierarchie 1]]&Tabelle1[[#This Row],[Händler]]&Tabelle1[[#This Row],[Kategorie]]&Tabelle1[[#This Row],[Gruppe]]&Tabelle1[[#This Row],[Name]] -> Edeka KonzernEdeka Hessenring (ZL)WürzsaucenWürzsaucen StandardWürzsauce Steak, 250ml | V174: =_xlfn.XLOOKUP(U174,'Daten Vor-Quartal'!U:U,'Daten Vor-Quartal'!I:I,0) -> 0.99090909
A175: Edeka Konzern | B175: Edeka Hessenring (ZL) | C175: Würzsaucen | D175: Würzsaucen Standard | E175: Würzsauce Tzatziki, 250ml | F175: 24 | G175: Completion | H175: 1 | I175: 0.98373984 | J175: 96.243228 | K175: 10.327371 | L175: 229 | M175: 229 | N175: 123 | O175: 121 | P175: 340 | Q175: 94.935839 | R175: -4.0409053 | S175: =V175 -> 0.98181818 | T175: =(Tabelle1[[#This Row],[MT Distri % (besucht)]]-Tabelle1[[#This Row],[MT Distri % (besucht) VP]])*100 -> 0.19216556 | U175: =Tabelle1[[#This Row],[Kundenhierarchie 1]]&Tabelle1[[#This Row],[Händler]]&Tabelle1[[#This Row],[Kategorie]]&Tabelle1[[#This Row],[Gruppe]]&Tabelle1[[#This Row],[Name]] -> Edeka KonzernEdeka Hessenring (ZL)WürzsaucenWürzsaucen StandardWürzsauce Tzatziki, 250ml | V175: =_xlfn.XLOOKUP(U175,'Daten Vor-Quartal'!U:U,'Daten Vor-Quartal'!I:I,0) -> 0.98181818
A176: Edeka Konzern | B176: Edeka Hessenring (ZL) | C176: Würzsaucen | D176: Würzsaucen Standard | E176: Würzsauce Unschuldsengel, 250ml | F176: 22 | G176: Completion | H176: 0 | I176: 0 | J176: 0 | K176: 0 | L176: 0 | M176: 229 | N176: 1 | O176: 0 | P176: 340 | Q176: 0 | R176: 0 | S176: =V176 -> 0 | T176: =(Tabelle1[[#This Row],[MT Distri % (besucht)]]-Tabelle1[[#This Row],[MT Distri % (besucht) VP]])*100 -> 0 | U176: =Tabelle1[[#This Row],[Kundenhierarchie 1]]&Tabelle1[[#This Row],[Händler]]&Tabelle1[[#This Row],[Kategorie]]&Tabelle1[[#This Row],[Gruppe]]&Tabelle1[[#This Row],[Name]] -> Edeka KonzernEdeka Hessenring (ZL)WürzsaucenWürzsaucen StandardWürzsauce Unschuldsengel, 250ml | V176: =_xlfn.XLOOKUP(U176,'Daten Vor-Quartal'!U:U,'Daten Vor-Quartal'!I:I,0) -> 0
A177: Edeka Konzern | B177: Edeka Minden (ZL + Lüning) | C177: Dressing | D177: Dressing 500ml | E177: Kühne Dressing 1000 Islands 0,5l | F177: 15 | G177: Ergänzung | H177: 0.98104956 | I177: 0.93905817 | J177: 78.819718 | K177: 3.0599001 | L177: 673 | M177: 686 | N177: 361 | O177: 339 | P177: 1015 | Q177: 95.865438 | R177: 1.3250061 | S177: =V177 -> 0.94150418 | T177: =(Tabelle1[[#This Row],[MT Distri % (besucht)]]-Tabelle1[[#This Row],[MT Distri % (besucht) VP]])*100 -> -0.24460065 | U177: =Tabelle1[[#This Row],[Kundenhierarchie 1]]&Tabelle1[[#This Row],[Händler]]&Tabelle1[[#This Row],[Kategorie]]&Tabelle1[[#This Row],[Gruppe]]&Tabelle1[[#This Row],[Name]] -> Edeka KonzernEdeka Minden (ZL + Lüning)DressingDressing 500mlKühne Dressing 1000 Islands 0,5l | V177: =_xlfn.XLOOKUP(U177,'Daten Vor-Quartal'!U:U,'Daten Vor-Quartal'!I:I,0) -> 0.94150418
A178: Edeka Konzern | B178: Edeka Minden (ZL + Lüning) | C178: Dressing | D178: Dressing 500ml | E178: Kühne Dressing American 0,5l | F178: 19 | G178: Ergänzung | H178: 0.95626822 | I178: 0.91066282 | J178: 65.792802 | K178: -0.81032829 | L178: 656 | M178: 686 | N178: 347 | O178: 316 | P178: 1015 | Q178: 91.193379 | R178: -0.077429846 | S178: =V178 -> 0.89306358 | T178: =(Tabelle1[[#This Row],[MT Distri % (besucht)]]-Tabelle1[[#This Row],[MT Distri % (besucht) VP]])*100 -> 1.759924 | U178: =Tabelle1[[#This Row],[Kundenhierarchie 1]]&Tabelle1[[#This Row],[Händler]]&Tabelle1[[#This Row],[Kategorie]]&Tabelle1[[#This Row],[Gruppe]]&Tabelle1[[#This Row],[Name]] -> Edeka KonzernEdeka Minden (ZL + Lüning)DressingDressing 500mlKühne Dressing American 0,5l | V178: =_xlfn.XLOOKUP(U178,'Daten Vor-Quartal'!U:U,'Daten Vor-Quartal'!I:I,0) -> 0.89306358
A179: Edeka Konzern | B179: Edeka Minden (ZL + Lüning) | C179: Dressing | D179: Dressing 500ml | E179: Kühne Dressing Balsamico 0,5l | F179: 18 | G179: Ergänzung | H179: 0.99562682 | I179: 0.94182825 | J179: 67.407847 | K179: -2.3345136 | L179: 683 | M179: 686 | N179: 361 | O179: 340 | P179: 1015 | Q179: 87.674511 | R179: 0.55440225 | S179: =V179 -> 0.9273743 | T179: =(Tabelle1[[#This Row],[MT Distri % (besucht)]]-Tabelle1[[#This Row],[MT Distri % (besucht) VP]])*100 -> 1.4453953 | U179: =Tabelle1[[#This Row],[Kundenhierarchie 1]]&Tabelle1[[#This Row],[Händler]]&Tabelle1[[#This Row],[Kategorie]]&Tabelle1[[#This Row],[Gruppe]]&Tabelle1[[#This Row],[Name]] -> Edeka KonzernEdeka Minden (ZL + Lüning)DressingDressing 500mlKühne Dressing Balsamico 0,5l | V179: =_xlfn.XLOOKUP(U179,'Daten Vor-Quartal'!U:U,'Daten Vor-Quartal'!I:I,0) -> 0.9273743
A180: Edeka Konzern | B180: Edeka Minden (ZL + Lüning) | C180: Dressing | D180: Dressing 500ml | E180: Kühne Dressing Caesar 0,5l | F180: 13 | G180: Ergänzung | H180: 0.94460641 | I180: 0.93628809 | J180: 76.540483 | K180: -0.74659979 | L180: 648 | M180: 686 | N180: 361 | O180: 338 | P180: 1015 | Q180: 90.749149 | R180: 0.66534228 | S180: =V180 -> 0.92067989 | T180: =(Tabelle1[[#This Row],[MT Distri % (besucht)]]-Tabelle1[[#This Row],[MT Distri % (besucht) VP]])*100 -> 1.5608202 | U180: =Tabelle1[[#This Row],[Kundenhierarchie 1]]&Tabelle1[[#This Row],[Händler]]&Tabelle1[[#This Row],[Kategorie]]&Tabelle1[[#This Row],[Gruppe]]&Tabelle1[[#This Row],[Name]] -> Edeka KonzernEdeka Minden (ZL + Lüning)DressingDressing 500mlKühne Dressing Caesar 0,5l | V180: =_xlfn.XLOOKUP(U180,'Daten Vor-Quartal'!U:U,'Daten Vor-Quartal'!I:I,0) -> 0.92067989
A181: Edeka Konzern | B181: Edeka Minden (ZL + Lüning) | C181: Dressing | D181: Dressing 500ml | E181: Kühne Dressing French 0,5l | F181: 10 | G181: Top (Hero) | H181: 0.98104956 | I181: 0.97229917 | J181: 72.419133 | K181: -0.96039202 | L181: 673 | M181: 686 | N181: 361 | O181: 351 | P181: 1015 | Q181: 93.128348 | R181: 0.95565546 | S181: =V181 -> 0.96100279 | T181: =(Tabelle1[[#This Row],[MT Distri % (besucht)]]-Tabelle1[[#This Row],[MT Distri % (besucht) VP]])*100 -> 1.1296383 | U181: =Tabelle1[[#This Row],[Kundenhierarchie 1]]&Tabelle1[[#This Row],[Händler]]&Tabelle1[[#This Row],[Kategorie]]&Tabelle1[[#This Row],[Gruppe]]&Tabelle1[[#This Row],[Name]] -> Edeka KonzernEdeka Minden (ZL + Lüning)DressingDressing 500mlKühne Dressing French 0,5l | V181: =_xlfn.XLOOKUP(U181,'Daten Vor-Quartal'!U:U,'Daten Vor-Quartal'!I:I,0) -> 0.96100279
A182: Edeka Konzern | B182: Edeka Minden (ZL + Lüning) | C182: Dressing | D182: Dressing 500ml | E182: Kühne Dressing Gartenkräuter 0,5l | F182: 16 | G182: Ergänzung | H182: 1 | I182: 0.9501385 | J182: 80.384189 | K182: 4.9071794 | L182: 686 | M182: 686 | N182: 361 | O182: 343 | P182: 1015 | Q182: 96.606166 | R182: 8.3388559 | S182: =V182 -> 0.94986072 | T182: =(Tabelle1[[#This Row],[MT Distri % (besucht)]]-Tabelle1[[#This Row],[MT Distri % (besucht) VP]])*100 -> 0.027777992 | U182: =Tabelle1[[#This Row],[Kundenhierarchie 1]]&Tabelle1[[#This Row],[Händler]]&Tabelle1[[#This Row],[Kategorie]]&Tabelle1[[#This Row],[Gruppe]]&Tabelle1[[#This Row],[Name]] -> Edeka KonzernEdeka Minden (ZL + Lüning)DressingDressing 500mlKühne Dressing Gartenkräuter 0,5l | V182: =_xlfn.XLOOKUP(U182,'Daten Vor-Quartal'!U:U,'Daten Vor-Quartal'!I:I,0) -> 0.94986072
A183: Edeka Konzern | B183: Edeka Minden (ZL + Lüning) | C183: Dressing | D183: Dressing 500ml | E183: Kühne Dressing Jogh.-Kräuter leicht 0,5l | F183: 5 | G183: Top (Hero) | H183: 1 | I183: 0.96398892 | J183: 71.966315 | K183: 2.1884094 | L183: 686 | M183: 686 | N183: 361 | O183: 348 | P183: 1015 | Q183: 92.891696 | R183: 6.7906947 | S183: =V183 -> 0.95264624 | T183: =(Tabelle1[[#This Row],[MT Distri % (besucht)]]-Tabelle1[[#This Row],[MT Distri % (besucht) VP]])*100 -> 1.134268 | U183: =Tabelle1[[#This Row],[Kundenhierarchie 1]]&Tabelle1[[#This Row],[Händler]]&Tabelle1[[#This Row],[Kategorie]]&Tabelle1[[#This Row],[Gruppe]]&Tabelle1[[#This Row],[Name]] -> Edeka KonzernEdeka Minden (ZL + Lüning)DressingDressing 500mlKühne Dressing Jogh.-Kräuter leicht 0,5l | V183: =_xlfn.XLOOKUP(U183,'Daten Vor-Quartal'!U:U,'Daten Vor-Quartal'!I:I,0) -> 0.95264624
A184: Edeka Konzern | B184: Edeka Minden (ZL + Lüning) | C184: Dressing | D184: Dressing 500ml | E184: Kühne Dressing Joghurt 0,5l | F184: 1 | G184: Top (Hero) | H184: 1 | I184: 0.98614958 | J184: 95.686696 | K184: -0.081137966 | L184: 686 | M184: 686 | N184: 361 | O184: 356 | P184: 1015 | Q184: 99.127595 | R184: 4.8452753 | S184: =V184 -> 0.99164345 | T184: =(Tabelle1[[#This Row],[MT Distri % (besucht)]]-Tabelle1[[#This Row],[MT Distri % (besucht) VP]])*100 -> -0.54938696 | U184: =Tabelle1[[#This Row],[Kundenhierarchie 1]]&Tabelle1[[#This Row],[Händler]]&Tabelle1[[#This Row],[Kategorie]]&Tabelle1[[#This Row],[Gruppe]]&Tabelle1[[#This Row],[Name]] -> Edeka KonzernEdeka Minden (ZL + Lüning)DressingDressing 500mlKühne Dressing Joghurt 0,5l | V184: =_xlfn.XLOOKUP(U184,'Daten Vor-Quartal'!U:U,'Daten Vor-Quartal'!I:I,0) -> 0.99164345
A185: Edeka Konzern | B185: Edeka Minden (ZL + Lüning) | C185: Dressing | D185: Dressing 500ml | E185: Kühne Dressing Kräuterwürzig 0,5l | F185: 2 | G185: Top (Hero) | H185: 1 | I185: 0.99168975 | J185: 93.008822 | K185: -1.1806792 | L185: 686 | M185: 686 | N185: 361 | O185: 358 | P185: 1015 | Q185: 98.929908 | R185: -0.35196441 | S185: =V185 -> 0.98050139 | T185: =(Tabelle1[[#This Row],[MT Distri % (besucht)]]-Tabelle1[[#This Row],[MT Distri % (besucht) VP]])*100 -> 1.1188358 | U185: =Tabelle1[[#This Row],[Kundenhierarchie 1]]&Tabelle1[[#This Row],[Händler]]&Tabelle1[[#This Row],[Kategorie]]&Tabelle1[[#This Row],[Gruppe]]&Tabelle1[[#This Row],[Name]] -> Edeka KonzernEdeka Minden (ZL + Lüning)DressingDressing 500mlKühne Dressing Kräuterwürzig 0,5l | V185: =_xlfn.XLOOKUP(U185,'Daten Vor-Quartal'!U:U,'Daten Vor-Quartal'!I:I,0) -> 0.98050139
... A3851: Rewe Gruppe | B3851: Wasgau | C3851: Würzsaucen | D3851: Würzsaucen Standard | E3851: Würzsauce Unschuldsengel, 250ml | F3851: 22 | G3851: Completion | H3851: 0 | I3851: 0 | J3851: 0 | K3851: 0 | L3851: 0 | M3851: 64 | N3851: 1 | O3851: 0 | P3851: 0 | Q3851: 0 | R3851: 0 | S3851: =V3851 -> 0 | T3851: =(Tabelle1[[#This Row],[MT Distri % (besucht)]]-Tabelle1[[#This Row],[MT Distri % (besucht) VP]])*100 -> 0 | U3851: =Tabelle1[[#This Row],[Kundenhierarchie 1]]&Tabelle1[[#This Row],[Händler]]&Tabelle1[[#This Row],[Kategorie]]&Tabelle1[[#This Row],[Gruppe]]&Tabelle1[[#This Row],[Name]] -> Rewe GruppeWasgauWürzsaucenWürzsaucen StandardWürzsauce Unschuldsengel, 250ml | V3851: =_xlfn.XLOOKUP(U3851,'Daten Vor-Quartal'!U:U,'Daten Vor-Quartal'!I:I,0) -> 0

Sheet Daten Vor-Quartal
A1: Kundenhierarchie 1 | B1: Händler | C1: Kategorie | D1: Gruppe | E1: Name | F1: Sortimentsranking | G1: SKU Type | H1: Listung % | I1: MT Distri % (besucht) | J1: IRi nDistr (ohne Promo) | K1: IRi nDistr VÄ vs. VJ | L1: Anzahl Stores – Listung | M1: Anzahl Stores - gesamt | N1: Anzahl Stores - besucht gesamt | O1: Anzahl Stores - besucht Distribution | P1: Circana - Anzahl Märkte | Q1: Cir gewDistr (ohne Promo) | R1: Cir gewDistr VÄ vs. VJ
A2: Edeka Konzern | B2: Edeka Hessenring (ZL) | C2: Dressing | D2: Dressing 500ml | E2: Kühne Dressing 1000 Islands 0,5l | F2: 15 | G2: Ergänzung | H2: 0 | I2: 0 | J2: 12.28957 | K2: 12.28957 | L2: 0 | M2: 229 | N2: 1 | O2: 0 | P2: 340 | Q2: 24.952655 | R2: 24.952655 | U2: =Tabelle2[[#This Row],[Kundenhierarchie 1]]&Tabelle2[[#This Row],[Händler]]&Tabelle2[[#This Row],[Kategorie]]&Tabelle2[[#This Row],[Gruppe]]&Tabelle2[[#This Row],[Name]] -> Edeka KonzernEdeka Hessenring (ZL)DressingDressing 500mlKühne Dressing 1000 Islands 0,5l
A3: Edeka Konzern | B3: Edeka Hessenring (ZL) | C3: Dressing | D3: Dressing 500ml | E3: Kühne Dressing American 0,5l | F3: 19 | G3: Ergänzung | H3: 0 | I3: 0 | J3: 12.28957 | K3: 12.28957 | L3: 0 | M3: 229 | N3: 1 | O3: 0 | P3: 340 | Q3: 24.952655 | R3: 24.952655 | U3: =Tabelle2[[#This Row],[Kundenhierarchie 1]]&Tabelle2[[#This Row],[Händler]]&Tabelle2[[#This Row],[Kategorie]]&Tabelle2[[#This Row],[Gruppe]]&Tabelle2[[#This Row],[Name]] -> Edeka KonzernEdeka Hessenring (ZL)DressingDressing 500mlKühne Dressing American 0,5l
A4: Edeka Konzern | B4: Edeka Hessenring (ZL) | C4: Dressing | D4: Dressing 500ml | E4: Kühne Dressing Balsamico 0,5l | F4: 18 | G4: Ergänzung | H4: 0 | I4: 0 | J4: 0 | K4: 0 | L4: 0 | M4: 229 | N4: 1 | O4: 0 | P4: 340 | Q4: 0 | R4: 0 | U4: =Tabelle2[[#This Row],[Kundenhierarchie 1]]&Tabelle2[[#This Row],[Händler]]&Tabelle2[[#This Row],[Kategorie]]&Tabelle2[[#This Row],[Gruppe]]&Tabelle2[[#This Row],[Name]] -> Edeka KonzernEdeka Hessenring (ZL)DressingDressing 500mlKühne Dressing Balsamico 0,5l
A5: Edeka Konzern | B5: Edeka Hessenring (ZL) | C5: Dressing | D5: Dressing 500ml | E5: Kühne Dressing Caesar 0,5l | F5: 13 | G5: Ergänzung | H5: 0 | I5: 0 | J5: 0 | K5: 0 | L5: 0 | M5: 229 | N5: 1 | O5: 0 | P5: 340 | Q5: 0 | R5: 0 | U5: =Tabelle2[[#This Row],[Kundenhierarchie 1]]&Tabelle2[[#This Row],[Händler]]&Tabelle2[[#This Row],[Kategorie]]&Tabelle2[[#This Row],[Gruppe]]&Tabelle2[[#This Row],[Name]] -> Edeka KonzernEdeka Hessenring (ZL)DressingDressing 500mlKühne Dressing Caesar 0,5l
A6: Edeka Konzern | B6: Edeka Hessenring (ZL) | C6: Dressing | D6: Dressing 500ml | E6: Kühne Dressing French 0,5l | F6: 10 | G6: Top (Hero) | H6: 1 | I6: 0.99090909 | J6: 75.223629 | K6: -3.246772 | L6: 229 | M6: 229 | N6: 110 | O6: 109 | P6: 340 | Q6: 87.446057 | R6: -11.649564 | U6: =Tabelle2[[#This Row],[Kundenhierarchie 1]]&Tabelle2[[#This Row],[Händler]]&Tabelle2[[#This Row],[Kategorie]]&Tabelle2[[#This Row],[Gruppe]]&Tabelle2[[#This Row],[Name]] -> Edeka KonzernEdeka Hessenring (ZL)DressingDressing 500mlKühne Dressing French 0,5l
A7: Edeka Konzern | B7: Edeka Hessenring (ZL) | C7: Dressing | D7: Dressing 500ml | E7: Kühne Dressing Gartenkräuter 0,5l | F7: 16 | G7: Ergänzung | H7: 1 | I7: 0.98181818 | J7: 78.092338 | K7: 2.8797597 | L7: 229 | M7: 229 | N7: 110 | O7: 108 | P7: 340 | Q7: 86.840081 | R7: -9.0233585 | U7: =Tabelle2[[#This Row],[Kundenhierarchie 1]]&Tabelle2[[#This Row],[Händler]]&Tabelle2[[#This Row],[Kategorie]]&Tabelle2[[#This Row],[Gruppe]]&Tabelle2[[#This Row],[Name]] -> Edeka KonzernEdeka Hessenring (ZL)DressingDressing 500mlKühne Dressing Gartenkräuter 0,5l
A8: Edeka Konzern | B8: Edeka Hessenring (ZL) | C8: Dressing | D8: Dressing 500ml | E8: Kühne Dressing Jogh.-Kräuter leicht 0,5l | F8: 5 | G8: Top (Hero) | H8: 1 | I8: 0.99090909 | J8: 76.284181 | K8: 3.142376 | L8: 229 | M8: 229 | N8: 110 | O8: 109 | P8: 340 | Q8: 98.089687 | R8: 2.5316534 | U8: =Tabelle2[[#This Row],[Kundenhierarchie 1]]&Tabelle2[[#This Row],[Händler]]&Tabelle2[[#This Row],[Kategorie]]&Tabelle2[[#This Row],[Gruppe]]&Tabelle2[[#This Row],[Name]] -> Edeka KonzernEdeka Hessenring (ZL)DressingDressing 500mlKühne Dressing Jogh.-Kräuter leicht 0,5l
A9: Edeka Konzern | B9: Edeka Hessenring (ZL) | C9: Dressing | D9: Dressing 500ml | E9: Kühne Dressing Joghurt 0,5l | F9: 1 | G9: Top (Hero) | H9: 1 | I9: 0.99090909 | J9: 85.997738 | K9: 3.5235899 | L9: 229 | M9: 229 | N9: 110 | O9: 109 | P9: 340 | Q9: 99.324435 | R9: 3.2170121 | U9: =Tabelle2[[#This Row],[Kundenhierarchie 1]]&Tabelle2[[#This Row],[Händler]]&Tabelle2[[#This Row],[Kategorie]]&Tabelle2[[#This Row],[Gruppe]]&Tabelle2[[#This Row],[Name]] -> Edeka KonzernEdeka Hessenring (ZL)DressingDressing 500mlKühne Dressing Joghurt 0,5l
